[2021-03-03 13:39:23,195] {taskinstance.py:851} INFO - Dependencies all met for <TaskInstance: postgres_operator_dag.create_pet_table 2021-03-03T10:39:22.545172+00:00 [queued]>
[2021-03-03 13:39:23,210] {taskinstance.py:851} INFO - Dependencies all met for <TaskInstance: postgres_operator_dag.create_pet_table 2021-03-03T10:39:22.545172+00:00 [queued]>
[2021-03-03 13:39:23,210] {taskinstance.py:1042} INFO - 
--------------------------------------------------------------------------------
[2021-03-03 13:39:23,210] {taskinstance.py:1043} INFO - Starting attempt 1 of 1
[2021-03-03 13:39:23,210] {taskinstance.py:1044} INFO - 
--------------------------------------------------------------------------------
[2021-03-03 13:39:23,219] {taskinstance.py:1063} INFO - Executing <Task(PostgresOperator): create_pet_table> on 2021-03-03T10:39:22.545172+00:00
[2021-03-03 13:39:23,221] {standard_task_runner.py:52} INFO - Started process 41752 to run task
[2021-03-03 13:39:23,223] {standard_task_runner.py:76} INFO - Running: ['airflow', 'tasks', 'run', 'postgres_operator_dag', 'create_pet_table', '2021-03-03T10:39:22.545172+00:00', '--job-id', '30', '--pool', 'default_pool', '--raw', '--subdir', 'DAGS_FOLDER/clickhouseLogging.py', '--cfg-path', '/tmp/tmppk6n3qq8', '--error-file', '/tmp/tmpr4rvtbzg']
[2021-03-03 13:39:23,224] {standard_task_runner.py:77} INFO - Job 30: Subtask create_pet_table
[2021-03-03 13:39:23,263] {logging_mixin.py:104} INFO - Running <TaskInstance: postgres_operator_dag.create_pet_table 2021-03-03T10:39:22.545172+00:00 [running]> on host oleg-desktop
[2021-03-03 13:39:23,310] {taskinstance.py:1255} INFO - Exporting the following env vars:
AIRFLOW_CTX_DAG_OWNER=airflow
AIRFLOW_CTX_DAG_ID=postgres_operator_dag
AIRFLOW_CTX_TASK_ID=create_pet_table
AIRFLOW_CTX_EXECUTION_DATE=2021-03-03T10:39:22.545172+00:00
AIRFLOW_CTX_DAG_RUN_ID=manual__2021-03-03T10:39:22.545172+00:00
[2021-03-03 13:39:23,311] {postgres.py:69} INFO - Executing: 
            CREATE TABLE IF NOT EXISTS pet (
            pet_id SERIAL PRIMARY KEY,
            name VARCHAR NOT NULL,
            pet_type VARCHAR NOT NULL,
            birth_date DATE NOT NULL,
            OWNER VARCHAR NOT NULL);
          
[2021-03-03 13:39:23,342] {base.py:65} INFO - Using connection to: id: postgres_default. Host: postgres, Port: None, Schema: airflow, Login: postgres, Password: XXXXXXXX, extra: None
[2021-03-03 13:39:23,343] {taskinstance.py:1455} ERROR - could not translate host name "postgres" to address: Temporary failure in name resolution
Traceback (most recent call last):
  File "/home/oleg/web/python/apacheAirflow/.venv/lib/python3.8/site-packages/airflow/models/taskinstance.py", line 1112, in _run_raw_task
    self._prepare_and_execute_task_with_callbacks(context, task)
  File "/home/oleg/web/python/apacheAirflow/.venv/lib/python3.8/site-packages/airflow/models/taskinstance.py", line 1285, in _prepare_and_execute_task_with_callbacks
    result = self._execute_task(context, task_copy)
  File "/home/oleg/web/python/apacheAirflow/.venv/lib/python3.8/site-packages/airflow/models/taskinstance.py", line 1315, in _execute_task
    result = task_copy.execute(context=context)
  File "/home/oleg/web/python/apacheAirflow/.venv/lib/python3.8/site-packages/airflow/providers/postgres/operators/postgres.py", line 71, in execute
    self.hook.run(self.sql, self.autocommit, parameters=self.parameters)
  File "/home/oleg/web/python/apacheAirflow/.venv/lib/python3.8/site-packages/airflow/hooks/dbapi.py", line 173, in run
    with closing(self.get_conn()) as conn:
  File "/home/oleg/web/python/apacheAirflow/.venv/lib/python3.8/site-packages/airflow/providers/postgres/hooks/postgres.py", line 108, in get_conn
    self.conn = psycopg2.connect(**conn_args)
  File "/home/oleg/web/python/apacheAirflow/.venv/lib/python3.8/site-packages/psycopg2/__init__.py", line 127, in connect
    conn = _connect(dsn, connection_factory=connection_factory, **kwasync)
psycopg2.OperationalError: could not translate host name "postgres" to address: Temporary failure in name resolution

[2021-03-03 13:39:23,344] {taskinstance.py:1496} INFO - Marking task as FAILED. dag_id=postgres_operator_dag, task_id=create_pet_table, execution_date=20210303T103922, start_date=20210303T103923, end_date=20210303T103923
[2021-03-03 13:39:23,394] {local_task_job.py:146} INFO - Task exited with return code 1
