[2021-03-03 16:15:04,280] {taskinstance.py:851} INFO - Dependencies all met for <TaskInstance: postgres_operator_dag.create_pet_table 2021-03-03T13:15:03.935531+00:00 [queued]>
[2021-03-03 16:15:04,301] {taskinstance.py:851} INFO - Dependencies all met for <TaskInstance: postgres_operator_dag.create_pet_table 2021-03-03T13:15:03.935531+00:00 [queued]>
[2021-03-03 16:15:04,301] {taskinstance.py:1042} INFO - 
--------------------------------------------------------------------------------
[2021-03-03 16:15:04,301] {taskinstance.py:1043} INFO - Starting attempt 1 of 1
[2021-03-03 16:15:04,301] {taskinstance.py:1044} INFO - 
--------------------------------------------------------------------------------
[2021-03-03 16:15:04,309] {taskinstance.py:1063} INFO - Executing <Task(PostgresOperator): create_pet_table> on 2021-03-03T13:15:03.935531+00:00
[2021-03-03 16:15:04,311] {standard_task_runner.py:52} INFO - Started process 69580 to run task
[2021-03-03 16:15:04,314] {standard_task_runner.py:76} INFO - Running: ['airflow', 'tasks', 'run', 'postgres_operator_dag', 'create_pet_table', '2021-03-03T13:15:03.935531+00:00', '--job-id', '18', '--pool', 'default_pool', '--raw', '--subdir', 'DAGS_FOLDER/clickhouseLogging.py', '--cfg-path', '/tmp/tmp6xrvgsq9', '--error-file', '/tmp/tmppb26khwl']
[2021-03-03 16:15:04,314] {standard_task_runner.py:77} INFO - Job 18: Subtask create_pet_table
[2021-03-03 16:15:04,348] {logging_mixin.py:104} INFO - Running <TaskInstance: postgres_operator_dag.create_pet_table 2021-03-03T13:15:03.935531+00:00 [running]> on host oleg-desktop
[2021-03-03 16:15:04,393] {taskinstance.py:1255} INFO - Exporting the following env vars:
AIRFLOW_CTX_DAG_OWNER=airflow
AIRFLOW_CTX_DAG_ID=postgres_operator_dag
AIRFLOW_CTX_TASK_ID=create_pet_table
AIRFLOW_CTX_EXECUTION_DATE=2021-03-03T13:15:03.935531+00:00
AIRFLOW_CTX_DAG_RUN_ID=manual__2021-03-03T13:15:03.935531+00:00
[2021-03-03 16:15:04,393] {postgres.py:69} INFO - Executing: SELECT * FROM dag;
[2021-03-03 16:15:04,424] {base.py:65} INFO - Using connection to: id: postgres_default. Host: postgres, Port: None, Schema: airflow, Login: postgres, Password: XXXXXXXX, extra: None
[2021-03-03 16:15:04,425] {taskinstance.py:1455} ERROR - could not translate host name "postgres" to address: Temporary failure in name resolution
Traceback (most recent call last):
  File "/home/oleg/web/python/apacheAirflow/.venv/lib/python3.8/site-packages/airflow/models/taskinstance.py", line 1112, in _run_raw_task
    self._prepare_and_execute_task_with_callbacks(context, task)
  File "/home/oleg/web/python/apacheAirflow/.venv/lib/python3.8/site-packages/airflow/models/taskinstance.py", line 1285, in _prepare_and_execute_task_with_callbacks
    result = self._execute_task(context, task_copy)
  File "/home/oleg/web/python/apacheAirflow/.venv/lib/python3.8/site-packages/airflow/models/taskinstance.py", line 1315, in _execute_task
    result = task_copy.execute(context=context)
  File "/home/oleg/web/python/apacheAirflow/.venv/lib/python3.8/site-packages/airflow/providers/postgres/operators/postgres.py", line 71, in execute
    self.hook.run(self.sql, self.autocommit, parameters=self.parameters)
  File "/home/oleg/web/python/apacheAirflow/.venv/lib/python3.8/site-packages/airflow/hooks/dbapi.py", line 173, in run
    with closing(self.get_conn()) as conn:
  File "/home/oleg/web/python/apacheAirflow/.venv/lib/python3.8/site-packages/airflow/providers/postgres/hooks/postgres.py", line 108, in get_conn
    self.conn = psycopg2.connect(**conn_args)
  File "/home/oleg/web/python/apacheAirflow/.venv/lib/python3.8/site-packages/psycopg2/__init__.py", line 127, in connect
    conn = _connect(dsn, connection_factory=connection_factory, **kwasync)
psycopg2.OperationalError: could not translate host name "postgres" to address: Temporary failure in name resolution

[2021-03-03 16:15:04,427] {taskinstance.py:1496} INFO - Marking task as FAILED. dag_id=postgres_operator_dag, task_id=create_pet_table, execution_date=20210303T131503, start_date=20210303T131504, end_date=20210303T131504
[2021-03-03 16:15:04,484] {local_task_job.py:146} INFO - Task exited with return code 1
